<mujocoinclude>
    <body name="wrist" pos="0 0 0.396">
        <inertial pos="0.003 0 0.016" quat="0.504234 0.49623 0.49523 0.504234" mass="0.3" diaginertia="0.001 0.001 0.001" />
        <geom name="V_wrist" class="D_Vizual" mesh="wrist" />
        <geom name="C_wrist" class="DC_Hand" size="0.015 0.01" quat="0.707107 0.707107 0 0" type="capsule" rgba="0.4 0.5 0.6 0.1" />
        <body name="palm" pos="0 0 0.034">
            <inertial pos="0.006 0 0.036" quat="0.715833 0.0439898 0.0749825 0.692839" mass="0.3" diaginertia="0.001 0.001 0.001" />
            <site name="S_grasp"  type="sphere" size="0.01" pos=".007 -.05 0.07" quat="0.0087 -0.6 -0.0034 -0.81  " rgba="0 0 0 0"/>



            <body pos="0 0 0.01" euler="0 -1.6 0">
                <!-- GRIPPER BASE-->
                <site name="sBase" pos="0.01 0 0" size="0.005 0 0" rgba="0 0 0 0"/>
                <geom class="base" size="0.058 0.04 0.01" pos="-0.01 0 0"/>
                <geom size="0.04 0.03 0.03" pos="-0.05 0 0" type="box" class="Silver"/>
                <!-- FINGERS LEFT -->
                <body pos="0 0.74 0" >
                    <body pos="0.01 -0.7 0">
                        <geom class="gripper_sticks_main" name="g121" />
                        <body pos="0.05 0 0" euler="0 0 -0.1">
                            <geom class="gripper_sticks_middle" name="g122"/>
                            <joint name="gripper_right" range="-0.1 1" limited="true" stiffness="100" springref="0"/>
                            <site name="s_gripper_right" pos="0 -0.08 0" size="0.005 0 0" rgba="0 0 0 0"/>
                            <body pos="0.06 -0.01 0" name="gripper_right_top" euler="0 0 -0.05">
                                <geom class="gripper_sticks_end" name="gripper_right_top" quat="0.2 0 0 1" />
<!--                                <joint name="gripper_right_top" range="-0.02 0.4"/>-->
                                <site name="s_gripper_right_top" pos="0 0 0" type="box" size="0.02 0.002 0.015" rgba="0 0 0 0" euler="0 0 -0.45"/>
                            </body>
                        </body>
                    </body>
                </body>

                <!-- FINGER RIGHT -->
                <body pos="0 0.66 0">
                    <body pos="0.01 -0.7 0">
                        <geom class="gripper_sticks_main" name="g21"/>
                        <body pos="0.05 0 0" euler="0 0 0.1">
                            <geom class="gripper_sticks_middle" name="g22" solimp="2 2"/>
                            <joint name="gripper_left" range="-1 0.1" limited="true" stiffness="100" springref="0"/>
                            <site name="s_gripper_left" pos="0 0.08 0" size="0.005 0 0" rgba="0 0 0 0"/>
                            <body pos="0.06 0.01 0" name="gripper_left_top" euler="0 0 0.05">
                                <geom class="gripper_sticks_end" name="gripper_left_top" quat="-0.3 0 0 1"/>
<!--                                <joint name="gripper_left_top" range="-0.4 0.02"/>-->
                                <site name="s_gripper_left_top" pos="0 0 0" type="box" size="0.02 0.002 0.015" rgba="0 0 0 0" euler="0 0 0.6"/>
                            </body>
                        </body>
                    </body>
                </body>
            </body>
        </body>
    </body>
</mujocoinclude>