<!-- ======================================================
    Model       :: ADROIT Door
 
    Mujoco      :: Advanced physics simulation engine
        Source      : www.roboti.us
        Version     : 1.50
        Released    : 17Jan'17
        
    Author      :: Vikash Kumar
        Contacts    : vikash@cs.washington.edu
        Last edits  : 17Jan'17

    Designed for :: Demo Augmented Policy Gradient (DAPG)

    Copyright   :: Vikash Kumar
        Licensed under Apache License, Version 2.0 (the "License"); you may not use this file except in compliance with the License. You may obtain a copy of the License at http://www.apache.org/licenses/LICENSE-2.0 Unless required by applicable law or agreed to in writing, software distributed under the License is distributed on an "AS IS" BASIS, WITHOUT WARRANTIES OR CONDITIONS OF ANY KIND, either express or implied. See the License for the specific language governing permissions and limitations under the License.
====================================================== -->

<mujoco model='ADROIT-door(v1.5)'>
    
    <!-- ======= WORLD ======= -->
    <worldbody>
        <light directional='false' diffuse='.7 .7 .7' specular='0.03 0.03 0.03' pos='-1 -1.0 4.0' dir='1 1.0 -4'/>
<!--        <geom name='ground' size="1.5 1.5 0.25" pos="0 0 -1" type="plane" contype="1" conaffinity="0" material="groundplane" />-->
        <camera name="fixed" pos="0.9 -0.7 0.7" quat="0.92388 0.382683 0 0" />
        <!-- Camera for the VIL paper -->
        <camera name="vil_camera" pos="0 -1.2 1.2" quat="0.92388 0.382683 0 0" />

        <!-- ======= MOCAP ======= -->
        <body name="vive_tracker" pos="0 -0.35 0.25" mocap="true">
            <inertial pos="0 0 0" mass="0.064" diaginertia="1.70667e-05 1.70667e-05 1.70667e-05" />
            <geom size="0.03 0.01" type="cylinder" contype="0" conaffinity="0" group="3" rgba="0.3 0.3 0.3 0.3" />
        </body>

        <!-- ======= HAND ======= -->
        <body name="forearm" pos="-0.6 -0.1 -0.04" euler="0 0 0">
            <inertial pos="0 0 0" mass="0.4"/>
            <joint name="ARTz_up" pos="0 0 0" axis="0 0 1" type="slide" range="0 0.05" stiffness="100.0" springref="-1.3" damping="100.0" />
            <joint name="ARRz" pos="0 0 0" axis="0 0 1" range="0 60" damping="20" stiffness="10"/>
            <geom name="V_forearm" class="D_Vizual" pos="0 -.01 .181" euler="0 0 -1.57"  mesh="forearm_simple" />
            <geom name="C_forearm1" class="DC_Hand" size="0.05 0.033" pos="0 0 0.29" type="capsule" rgba="0.4 0.5 0.6 0.1" />

            <!-- ======= Adroit ======= -->
            <include file="wrench_in_model.xml"/>
        </body>

        <!-- ======= Satellite ======= -->
        <body name="satelite" pos="0.2 0.97 -0.9" euler="2.33 4.6 3.14" >
            <inertial pos="0 0 0" mass="4"/>
            <geom name="Satellite" class="Satellite" pos="0 -.5 .2" euler="10 10 -11.57"  mesh="Satellite" size="0.05 0.25"/>

            <body name="frame" pos="-0.107339 0.0435293 0.447376" user="1001 0 2002 -0.4 -0.1 0.252 0 0.3 0.45" axisangle="0 0 1 -0.8">
            <geom size="0.02 0.2" pos="1.68 -0.88 0.23" type="cylinder" material="MatWood" euler="-0.1 4.63 0"/>
            <geom size="0.02 0.2" pos="1.72 -0.93 -0.23" type="cylinder" material="MatWood" euler="-0.1 4.63 0"/>
<!--            <site name="S_handle_target" pos="0.75 -0.5 -.18" size="0.025" group='3'/>-->
            <body name="door" pos="1.7 -0.9 0" euler="-0.1 4.63 0">
<!--                <geom size="0.01 0.2" pos="0.2 0 0" type="cylinder" material="MatWood" />-->
<!--                <geom size="0.01 0.2" pos="-0.2 0 0" type="cylinder" material="MatWood" />-->
                <body name="door_main" pos="0.4 -0.2 0" euler="0 0 2.5">
<!--                <joint name="door_hinge" pos="0.31 0 0" axis="0 0 1" range="0 1.57" damping="1" frictionloss="2" />-->
                <geom size="0.2 0.01 0.2" type="box" friction="1 1 1" material="MatWood" name="door"/>
                <body name="latch" pos="-0.2 0.05 -0.025" euler="0.15 0 0">
                   <geom size="0.01 0.06" pos="0.1 -0.08 0" quat="0.707388 0.706825 0 0" type="cylinder" material="MatFoil" />
                    <geom size="0.01 0.1" pos="0.1 -0.14 0" quat="0.707388 10 0.706825 0" type="capsule" material="MatFoil" />
                    <geom size="0.01 0.05" pos="0.1 -0.03 0" quat="0.707388 0 0.706825 0" type="capsule" material="MatFoil" />



<!--                    <site name="S_handle" pos="0.15 -0.15 0" size="0.025" group='3'/>-->
                </body>
                    <body name="si_unit" pos="0 0.02 -0.01" euler="0 0 0">
                    <geom name="si_unit" size="0.16 0.045 0.16" type="box" friction="1 1 1" rgba="0.5 0.5 0.5 0.5" />
                    <body pos="0 0.031 0">
                        <geom pos="0 0 0.14" euler="0 0 0" class="bolt" mesh="bolt" name="bolt"/>
                        <site name="bolt" pos="0 0.001 0.17" size="0.01 0 0" group='3' rgba="0 0 0 0"/>
                        <body euler="0 0 0" name="nut" pos="0 0 0.03">
                            <site name="S_nut" pos="0 0.001 0.17" size="0.005 0 0" group='3' rgba="0 0 0 0"/>
                            <geom name="nut" pos="0 0 0.165" euler="0 0 0" class="nut" mesh="nut"/>
                            <joint name="nut_around" pos="0 0 0" axis="0 0 -1" type="hinge" range="0 19" damping="0" stiffness="0"/>
                            <joint name="nut_upwards" pos="0 0 0" axis="0 0 -1" type="slide" range="0 0.048" damping="1" stiffness="0" springref="10"/>
                        </body>

                        <body pos="0.12 0.02 -0.1" euler="0 0 0">
                            <geom size="0.001 0.001 0.001" pos="0 -0.05 0" type="box" friction="1 1 1" rgba="0.5 0.5 0.5 0.5"  name="screw_box"/>
                            <site name="S_door" pos="0 0 0" size="0.004 0 0" group='3' rgba="0 0 0 0"/>
                            <body name="screw" pos="0 0 0" >
                                <site name="S_screw" pos="0 -0.0006 0" size="0.005 0 0" group='3' rgba="1 0 0 0.5"/>
                                <geom pos="0 0 0" euler="0 0 1.57" class="screw" mesh="screw" name="screw"/>
                                <body>
                                    <site name="S_screw_extension_1" pos="-0.008 0.01 0" size="0.0005 0 0" group='3' rgba="0 0 0 0"/>
                                    <geom pos="-0.011 0.008 0.0145" euler="0 1.54 0" mesh="semi_cylinder" name="screw_extension_1" class="screw"/>
                                    <site name="S_screw_extension_2" pos="0.005 0.01 0" size="0.0005 0 0" group='3' rgba="0 0 0 0"/>
                                    <geom pos="0.01 0.008 -0.0152" euler="0 -1.53 0" mesh="semi_cylinder" name="screw_extension_2" class="screw"/>
                                </body>
                            </body>
                        </body>
                    </body>
                </body>
            </body>
                </body>
        </body>




            <!-- ======= Adroit ======= -->
            <include file="../HST.xml"/>
        </body>
    </worldbody>

    <actuator>
        <general name="A_ARRz" joint="ARRz" ctrlrange="0 50" biastype="affine" gainprm="100 0 0" biasprm="0 -100 0"/>
<!--        <general name="A_ARTz_up" joint="ARTz_up" ctrlrange="0 100" biastype="affine" gainprm="100 0 0" biasprm="0 -100 0" />-->

<!--        <adhesion name="adhere_gripper_left" body="gripper_left_top" ctrlrange="0 100" gain="500"/>-->
<!--        <adhesion name="adhere_gripper_right" body="gripper_right_top" ctrlrange="0 100" gain="500"/>-->
<!--        <adhesion name="adhere_nut" body="nut" ctrlrange="0 100" gain="500"/>-->
    </actuator>

    <equality>
        <joint name="connected_joints" active="true" joint1="nut_around" joint2="nut_upwards" polycoef="0 300 1 0 0"/>
<!--        <joint name="connected_joints_hand" active="true" joint1="ARRz" joint2="ARTz_up" polycoef="0 300 1 0 0"/>-->

    </equality>


<!--        <equality>-->
<!--        <joint name="connected_joints_gripper" active="true" joint1="gripper_right" joint2="gripper_left" solimplimit="1 1 1" solreflimit="1 1 1" />-->
<!--    </equality>-->
    <include file='wrench_in_assets.xml'/>


</mujoco>
